<?xml version="1.0" encoding="utf-8"?>
<!-- This URDF was automatically created by SolidWorks to URDF Exporter! Originally created by Stephen Brawner (brawner@gmail.com) 
     Commit Version: 1.6.0-1-g15f4949  Build Version: 1.6.7594.29634
     For more information, please see http://wiki.ros.org/sw_urdf_exporter -->
<robot name="ros_robot" xmlns:xacro="http://ros.org/wiki/xacro">
<!-- Included URDF/XACRO Files -->
<xacro:include filename="$(find ros_robot)/urdf/plugins_ros_robot.xacro" />
<!--xacro:arg name="robot_namespace" default="/ros_robot" /-->

  <!-- base_link is the center of the robot's bottom plate -->
  <link name="base_link">
    <!-- base_link can't contain inertial element, because it's a parent link (Global Origin) -->
    <!--inertial>
      <origin xyz="-0.0021885 2.0281E-05 -0.027557" rpy="0 0 0" />
      <mass value="20" />
      <inertia  ixx="0.030111"  ixy="-0.0015236" ixz="6.7859E-07"
                iyy="0.050604" iyz="-7.5891E-10"
                izz="0.071292" />
    </inertial-->

    <visual>
      <origin xyz="0 0 0" rpy="0 0 0" />
      <geometry>
        <mesh filename="package://ros_robot/meshes/base_link.STL" />
      </geometry>
      <material name="">
        <color rgba="0.79216 0.81961 0.93333 1" />
      </material>
    </visual>

    <collision> <origin xyz="0 0 0"  rpy="0 0 0" />
      <geometry>
        <mesh filename="package://ros_robot/meshes/base_link.STL" />
      </geometry>
    </collision>
  </link>
  
  <!-- base_footprint is on the ground under the robot -->
  <link name="base_footprint"/>

  <joint name="base_footprint_joint" type="fixed">
    <origin xyz="0 0 -0.254" rpy="0 0 0" />
    <parent link="base_link" />
    <child link="base_footprint" />
  </joint>
  
  <!-- inertial_link stores the robot's inertial information -->
  <link name="inertial_link">
    <inertial>
      <origin xyz="-0.0021885 2.0281E-05 -0.027557" rpy="0 0 0" />
      <mass value="20" />
      <inertia  ixx="0.030111"  ixy="-0.0015236" ixz="6.7859E-07"
                iyy="0.050604" iyz="-7.5891E-10"
                izz="0.071292" />
    </inertial>
  </link>

  <joint name="inertial_joint" type="fixed">
    <origin xyz="0 0 0" rpy="0 0 0" />
    <parent link="base_link" />
    <child link="inertial_link" />
  </joint>

  <!-- right_front_wheel -->
  <link name="right_front_wheel">
    <inertial>
      <origin  xyz="-2.498E-16 -0.05125 6.9389E-17" rpy="0 0 0" />
      <mass value="3" />
      <inertia ixx="0.047709" ixy="9.1909E-18" ixz="-1.4307E-19"
               iyy="0.087893" iyz="-4.6646E-18"
               izz="0.047709" />
    </inertial>

    <visual>
      <origin xyz="0 0 0" rpy="0 0 0" />
      <geometry>
        <mesh filename="package://ros_robot/meshes/right_front_wheel.STL" />
      </geometry>
      <material name="">
        <color rgba="0.79216 0.81961 0.93333 1" />
      </material>
    </visual>

    <collision>
      <origin xyz="0 0 0" rpy="0 0 0" />
      <geometry>
        <mesh filename="package://ros_robot/meshes/right_front_wheel.STL" />
      </geometry>
    </collision>
  </link>
  
  <joint name="right_front_wheel_joint" type="continuous">
    <origin xyz="0.21 -0.2265 -0.089008" rpy="0 0 0" />
    <parent link="base_link" />
    <child link="right_front_wheel" />
    <axis xyz="0 1 0" />
  </joint>
  
  <!-- left_front_wheel -->
  <link
    name="left_front_wheel">
    <inertial>
      <origin xyz="8.3267E-17 0.05125 1.5266E-16" rpy="0 0 0" />
      <mass value="3" />
      <inertia ixx="0.047709" ixy="-3.9925E-20" ixz="7.7645E-19"
               iyy="0.087893" iyz="-1.6815E-17"
               izz="0.047709" />
    </inertial>

    <visual>
      <origin xyz="0 0 0" rpy="0 0 0" />
      <geometry>
        <mesh filename="package://ros_robot/meshes/left_front_wheel.STL" />
      </geometry>
      <material name="">
        <color rgba="0.79216 0.81961 0.93333 1" />
      </material>
    </visual>

    <collision>
      <origin xyz="0 0 0" rpy="0 0 0" />
      <geometry>
        <mesh filename="package://ros_robot/meshes/left_front_wheel.STL" />
      </geometry>
    </collision>
  </link>

  <joint name="left_front_wheel_joint" type="continuous">
    <origin xyz="0.21 0.2265 -0.089008" rpy="0 0 0" />
    <parent link="base_link" />
    <child link="left_front_wheel" />
    <axis xyz="0 1 0" />
  </joint>

  <!-- right_rear_wheel -->
  <link name="right_rear_wheel">
    <inertial>
      <origin xyz="0 -0.05125 5.5511E-17" rpy="0 0 0" />
      <mass value="3" />
      <inertia ixx="0.047709" ixy="6.9064E-18" ixz="4.2983E-19"
               iyy="0.087893" iyz="-4.4799E-18"
               izz="0.047709" />
    </inertial>

    <visual>
      <origin xyz="0 0 0" rpy="0 0 0" />
      <geometry>
        <mesh filename="package://ros_robot/meshes/right_rear_wheel.STL" />
      </geometry>
      <material name="">
        <color rgba="0.79216 0.81961 0.93333 1" />
      </material>
    </visual>

    <collision>
      <origin xyz="0 0 0" rpy="0 0 0" />
      <geometry>
        <mesh filename="package://ros_robot/meshes/right_rear_wheel.STL" />
      </geometry>
    </collision>
  </link>

  <joint name="right_rear_wheel_joint" type="continuous">
    <origin xyz="-0.21 -0.2265 -0.089" rpy="0 0 0" />
    <parent link="base_link" />
    <child link="right_rear_wheel" />
    <axis xyz="0 1 0" />
  </joint>

  <!-- left_rear_wheel -->
  <link name="left_rear_wheel">
    <inertial>
      <origin xyz="8.3267E-17 0.05125 -2.7756E-17" rpy="0 0 0" />
      <mass value="3" />
      <inertia ixx="0.047709" ixy="6.6234E-18" ixz="-4.9623E-18"
               iyy="0.087893" iyz="-7.8363E-18"
               izz="0.047709" />
    </inertial>

    <visual>
      <origin xyz="0 0 0" rpy="0 0 0" />
      <geometry>
        <mesh filename="package://ros_robot/meshes/left_rear_wheel.STL" />
      </geometry>
      <material name="">
        <color rgba="0.79216 0.81961 0.93333 1" />
      </material>
    </visual>

    <collision>
      <origin xyz="0 0 0" rpy="0 0 0" />
      <geometry>
        <mesh filename="package://ros_robot/meshes/left_rear_wheel.STL" />
      </geometry>
    </collision>
  </link>

  <joint name="left_rear_wheel_joint" type="continuous">
    <origin xyz="-0.21 0.2265 -0.089" rpy="0 0 0" />
    <parent link="base_link" />
    <child link="left_rear_wheel" />
    <axis xyz="0 1 0" />
  </joint>

  <!-- imu_link -->
  <link name="imu_link">
    <inertial>
      <origin xyz="-0.0016551 0.00010771 -0.0010195" rpy="0 0 0" />
      <mass value="0.00052939" />
      <inertia ixx="1.3329E-08" ixy="5.7265E-12" ixz="-6.2461E-14"
               iyy="7.5622E-09" iyz="3.368E-18"
               izz="1.9976E-08" />
    </inertial>

    <visual>
      <origin xyz="0 0 0" rpy="0 0 0" />
      <geometry>
        <mesh filename="package://ros_robot/meshes/imu_link.STL" />
      </geometry>
      <material name="">
        <color rgba="0.79216 0.81961 0.93333 1" />
      </material>
    </visual>

    <collision>
      <origin xyz="0 0 0" rpy="0 0 0" />
      <geometry>
        <mesh filename="package://ros_robot/meshes/imu_link.STL" />
      </geometry>
    </collision>
  </link>

  <joint name="imu_joint" type="fixed">
    <origin xyz="0 0 0" rpy="0 0 0" />
    <parent link="base_link" />
    <child link="imu_link" />
    <axis xyz="0 0 0" />
  </joint>

  <!-- lidar_link -->
  <link name="lidar_link">
    <inertial>
      <origin xyz="0.0082697 1.4922E-15 -0.0094513" rpy="0 0 0" />
      <mass value="0.1489" />
      <inertia ixx="7.2162E-05" ixy="-3.5845E-19" ixz="1.8621E-05"
               iyy="0.00011961" iyz="1.3141E-19"
               izz="0.00012931" />
    </inertial>

    <visual>
      <origin xyz="0 0 0" rpy="0 0 0" />
      <geometry>
        <mesh filename="package://ros_robot/meshes/lidar_link.STL" />
      </geometry>
      <material name="">
        <color rgba="0.79216 0.81961 0.93333 1" />
      </material>
    </visual>

    <collision>
      <origin xyz="0 0 0" rpy="0 0 0" />
      <geometry>
        <mesh filename="package://ros_robot/meshes/lidar_link.STL" />
      </geometry>
    </collision>
  </link>

  <joint name="lidar_joint" type="fixed">
    <origin xyz="-0.0445 0 0.16575" rpy="0 0 0" />
    <parent link="base_link" />
    <child link="lidar_link" />
    <axis xyz="0 0 0" />
  </joint>

  <!-- kinect_link -->
  <link name="kinect_link">
    <inertial>
      <origin xyz="0.0012646 4.542E-05 -0.0064888" rpy="0 0 0" />
      <mass value="0.65666" />
      <inertia ixx="0.0029859" ixy="-9.3802E-07" ixz="9.6554E-08"
               iyy="0.00026948" iyz="1.3766E-08"
               izz="0.0031116" />
    </inertial>

    <visual>
      <origin xyz="0 0 0" rpy="0 0 0" />
      <geometry>
        <mesh filename="package://ros_robot/meshes/kinect_link.STL" />
      </geometry>
      <material name="">
        <color rgba="0.79216 0.81961 0.93333 1" />
      </material>
    </visual>

    <collision>
      <origin xyz="0 0 0" rpy="0 0 0" />
      <geometry>
        <mesh filename="package://ros_robot/meshes/kinect_link.STL" />
      </geometry>
    </collision>
  </link>

  <joint name="kinect_joint" type="fixed">
    <origin xyz="0.21125 0 0.12827" rpy="0 0 0" />
    <parent link="base_link" />
    <child link="kinect_link" />
    <axis xyz="0 0 0" />
  </joint>

  <!-- camera_link -->
  <link name="camera_link">
    <inertial>
      <origin xyz="-0.0049973 -2.7081E-05 0.0066457" rpy="0 0 0" />
      <mass value="0.0020855" />
      <inertia ixx="2.7457E-07" ixy="3.1734E-11" ixz="1.0398E-09"
               iyy="8.7372E-08" iyz="4.2706E-10"
               izz="1.9627E-07" />
    </inertial>

    <visual>
      <origin xyz="0 0 0" rpy="0 0 0" />
      <geometry>
        <mesh filename="package://ros_robot/meshes/camera_link.STL" />
      </geometry>
      <material name="">
        <color rgba="0.79216 0.81961 0.93333 1" />
      </material>
    </visual>

    <collision>
      <origin xyz="0 0 0" rpy="0 0 0" />
      <geometry>
        <mesh
          filename="package://ros_robot/meshes/camera_link.STL" />
      </geometry>
    </collision>
  </link>

  <joint name="camera_joint" type="fixed">
    <origin xyz="0.3121 0 0.00895" rpy="0 0 0" />
    <parent link="base_link" />
    <child link="camera_link" />
    <axis xyz="0 0 0" />
  </joint>
</robot>
